[2023-10-01T17:12:46.555+0000] {taskinstance.py:1103} INFO - Dependencies all met for dep_context=non-requeueable deps ti=<TaskInstance: Load-Green-Taxi-Data-Web-To-GCS-To-BQ.download_to_gcs scheduled__2019-05-02T06:00:00+00:00 [queued]>
[2023-10-01T17:12:46.574+0000] {taskinstance.py:1103} INFO - Dependencies all met for dep_context=requeueable deps ti=<TaskInstance: Load-Green-Taxi-Data-Web-To-GCS-To-BQ.download_to_gcs scheduled__2019-05-02T06:00:00+00:00 [queued]>
[2023-10-01T17:12:46.575+0000] {taskinstance.py:1308} INFO - Starting attempt 3 of 3
[2023-10-01T17:12:47.118+0000] {taskinstance.py:1327} INFO - Executing <Task(WebToGCSHKOperator): download_to_gcs> on 2019-05-02 06:00:00+00:00
[2023-10-01T17:12:47.127+0000] {standard_task_runner.py:57} INFO - Started process 1998 to run task
[2023-10-01T17:12:47.130+0000] {standard_task_runner.py:84} INFO - Running: ['***', 'tasks', 'run', 'Load-Green-Taxi-Data-Web-To-GCS-To-BQ', 'download_to_gcs', 'scheduled__2019-05-02T06:00:00+00:00', '--job-id', '592', '--raw', '--subdir', 'DAGS_FOLDER/web_gcs_bq.py', '--cfg-path', '/tmp/tmp3lfhk8hw']
[2023-10-01T17:12:47.133+0000] {standard_task_runner.py:85} INFO - Job 592: Subtask download_to_gcs
[2023-10-01T17:12:47.821+0000] {task_command.py:410} INFO - Running <TaskInstance: Load-Green-Taxi-Data-Web-To-GCS-To-BQ.download_to_gcs scheduled__2019-05-02T06:00:00+00:00 [running]> on host 772c7a5949f4
[2023-10-01T17:12:48.796+0000] {taskinstance.py:1547} INFO - Exporting env vars: AIRFLOW_CTX_DAG_EMAIL='' AIRFLOW_CTX_DAG_OWNER='***' AIRFLOW_CTX_DAG_ID='Load-Green-Taxi-Data-Web-To-GCS-To-BQ' AIRFLOW_CTX_TASK_ID='download_to_gcs' AIRFLOW_CTX_EXECUTION_DATE='2019-05-02T06:00:00+00:00' AIRFLOW_CTX_TRY_NUMBER='3' AIRFLOW_CTX_DAG_RUN_ID='scheduled__2019-05-02T06:00:00+00:00'
[2023-10-01T17:12:48.797+0000] {crypto.py:83} WARNING - empty cryptography key - values will not be stored encrypted.
[2023-10-01T17:12:48.798+0000] {base.py:73} INFO - Using connection ID 'google_cloud_default' for task execution.
[2023-10-01T17:12:48.798+0000] {Web_To_GCS_Hook.py:67} INFO - Execute downloading of file from https://github.com/DataTalksClub/nyc-tlc-data/releases/download/green/green_tripdata_2019-05.csv.gz to gs://practice18//green_tripdata_2019-05.csv.gz
[2023-10-01T17:12:48.803+0000] {taskinstance.py:1824} ERROR - Task failed with exception
Traceback (most recent call last):
  File "/home/airflow/.local/lib/python3.7/site-packages/urllib3/connection.py", line 175, in _new_conn
    (self._dns_host, self.port), self.timeout, **extra_kw
  File "/home/airflow/.local/lib/python3.7/site-packages/urllib3/util/connection.py", line 72, in create_connection
    for res in socket.getaddrinfo(host, port, family, socket.SOCK_STREAM):
  File "/usr/local/lib/python3.7/socket.py", line 752, in getaddrinfo
    for res in _socket.getaddrinfo(host, port, family, type, proto, flags):
socket.gaierror: [Errno -3] Temporary failure in name resolution

During handling of the above exception, another exception occurred:

Traceback (most recent call last):
  File "/home/airflow/.local/lib/python3.7/site-packages/urllib3/connectionpool.py", line 721, in urlopen
    chunked=chunked,
  File "/home/airflow/.local/lib/python3.7/site-packages/urllib3/connectionpool.py", line 403, in _make_request
    self._validate_conn(conn)
  File "/home/airflow/.local/lib/python3.7/site-packages/urllib3/connectionpool.py", line 1053, in _validate_conn
    conn.connect()
  File "/home/airflow/.local/lib/python3.7/site-packages/urllib3/connection.py", line 363, in connect
    self.sock = conn = self._new_conn()
  File "/home/airflow/.local/lib/python3.7/site-packages/urllib3/connection.py", line 187, in _new_conn
    self, "Failed to establish a new connection: %s" % e
urllib3.exceptions.NewConnectionError: <urllib3.connection.HTTPSConnection object at 0x7fef855033d0>: Failed to establish a new connection: [Errno -3] Temporary failure in name resolution

During handling of the above exception, another exception occurred:

Traceback (most recent call last):
  File "/home/airflow/.local/lib/python3.7/site-packages/requests/adapters.py", line 497, in send
    chunked=chunked,
  File "/home/airflow/.local/lib/python3.7/site-packages/urllib3/connectionpool.py", line 799, in urlopen
    method, url, error=e, _pool=self, _stacktrace=sys.exc_info()[2]
  File "/home/airflow/.local/lib/python3.7/site-packages/urllib3/util/retry.py", line 592, in increment
    raise MaxRetryError(_pool, url, error or ResponseError(cause))
urllib3.exceptions.MaxRetryError: HTTPSConnectionPool(host='github.com', port=443): Max retries exceeded with url: /DataTalksClub/nyc-tlc-data/releases/download/green/green_tripdata_2019-05.csv.gz (Caused by NewConnectionError('<urllib3.connection.HTTPSConnection object at 0x7fef855033d0>: Failed to establish a new connection: [Errno -3] Temporary failure in name resolution'))

During handling of the above exception, another exception occurred:

Traceback (most recent call last):
  File "/opt/airflow/plugins/web/operators/Web_To_GCS_Hook.py", line 58, in execute
    self._copy_file_object(gcs_hook)
  File "/opt/airflow/plugins/web/operators/Web_To_GCS_Hook.py", line 75, in _copy_file_object
    r = requests.get(request_url)
  File "/home/airflow/.local/lib/python3.7/site-packages/requests/api.py", line 73, in get
    return request("get", url, params=params, **kwargs)
  File "/home/airflow/.local/lib/python3.7/site-packages/requests/api.py", line 59, in request
    return session.request(method=method, url=url, **kwargs)
  File "/home/airflow/.local/lib/python3.7/site-packages/requests/sessions.py", line 589, in request
    resp = self.send(prep, **send_kwargs)
  File "/home/airflow/.local/lib/python3.7/site-packages/requests/sessions.py", line 703, in send
    r = adapter.send(request, **kwargs)
  File "/home/airflow/.local/lib/python3.7/site-packages/requests/adapters.py", line 519, in send
    raise ConnectionError(e, request=request)
requests.exceptions.ConnectionError: HTTPSConnectionPool(host='github.com', port=443): Max retries exceeded with url: /DataTalksClub/nyc-tlc-data/releases/download/green/green_tripdata_2019-05.csv.gz (Caused by NewConnectionError('<urllib3.connection.HTTPSConnection object at 0x7fef855033d0>: Failed to establish a new connection: [Errno -3] Temporary failure in name resolution'))
[2023-10-01T17:12:48.815+0000] {taskinstance.py:1350} INFO - Marking task as FAILED. dag_id=Load-Green-Taxi-Data-Web-To-GCS-To-BQ, task_id=download_to_gcs, execution_date=20190502T060000, start_date=20231001T171246, end_date=20231001T171248
[2023-10-01T17:12:48.835+0000] {warnings.py:110} WARNING - /home/***/.local/lib/python3.7/site-packages/***/utils/email.py:153: RemovedInAirflow3Warning: Fetching SMTP credentials from configuration variables will be deprecated in a future release. Please set credentials using a connection instead.
  send_mime_email(e_from=mail_from, e_to=recipients, mime_msg=msg, conn_id=conn_id, dryrun=dryrun)

[2023-10-01T17:12:48.835+0000] {configuration.py:673} WARNING - section/key [smtp/smtp_user] not found in config
[2023-10-01T17:12:48.835+0000] {email.py:269} INFO - Email alerting: attempt 1
[2023-10-01T17:12:48.844+0000] {configuration.py:673} WARNING - section/key [smtp/smtp_user] not found in config
[2023-10-01T17:12:48.845+0000] {email.py:269} INFO - Email alerting: attempt 1
[2023-10-01T17:12:48.846+0000] {taskinstance.py:1889} ERROR - Failed to send email to: ['']
Traceback (most recent call last):
  File "/home/airflow/.local/lib/python3.7/site-packages/urllib3/connection.py", line 175, in _new_conn
    (self._dns_host, self.port), self.timeout, **extra_kw
  File "/home/airflow/.local/lib/python3.7/site-packages/urllib3/util/connection.py", line 72, in create_connection
    for res in socket.getaddrinfo(host, port, family, socket.SOCK_STREAM):
  File "/usr/local/lib/python3.7/socket.py", line 752, in getaddrinfo
    for res in _socket.getaddrinfo(host, port, family, type, proto, flags):
socket.gaierror: [Errno -3] Temporary failure in name resolution

During handling of the above exception, another exception occurred:

Traceback (most recent call last):
  File "/home/airflow/.local/lib/python3.7/site-packages/urllib3/connectionpool.py", line 721, in urlopen
    chunked=chunked,
  File "/home/airflow/.local/lib/python3.7/site-packages/urllib3/connectionpool.py", line 403, in _make_request
    self._validate_conn(conn)
  File "/home/airflow/.local/lib/python3.7/site-packages/urllib3/connectionpool.py", line 1053, in _validate_conn
    conn.connect()
  File "/home/airflow/.local/lib/python3.7/site-packages/urllib3/connection.py", line 363, in connect
    self.sock = conn = self._new_conn()
  File "/home/airflow/.local/lib/python3.7/site-packages/urllib3/connection.py", line 187, in _new_conn
    self, "Failed to establish a new connection: %s" % e
urllib3.exceptions.NewConnectionError: <urllib3.connection.HTTPSConnection object at 0x7fef855033d0>: Failed to establish a new connection: [Errno -3] Temporary failure in name resolution

During handling of the above exception, another exception occurred:

Traceback (most recent call last):
  File "/home/airflow/.local/lib/python3.7/site-packages/requests/adapters.py", line 497, in send
    chunked=chunked,
  File "/home/airflow/.local/lib/python3.7/site-packages/urllib3/connectionpool.py", line 799, in urlopen
    method, url, error=e, _pool=self, _stacktrace=sys.exc_info()[2]
  File "/home/airflow/.local/lib/python3.7/site-packages/urllib3/util/retry.py", line 592, in increment
    raise MaxRetryError(_pool, url, error or ResponseError(cause))
urllib3.exceptions.MaxRetryError: HTTPSConnectionPool(host='github.com', port=443): Max retries exceeded with url: /DataTalksClub/nyc-tlc-data/releases/download/green/green_tripdata_2019-05.csv.gz (Caused by NewConnectionError('<urllib3.connection.HTTPSConnection object at 0x7fef855033d0>: Failed to establish a new connection: [Errno -3] Temporary failure in name resolution'))

During handling of the above exception, another exception occurred:

Traceback (most recent call last):
  File "/home/airflow/.local/lib/python3.7/site-packages/airflow/models/taskinstance.py", line 1407, in _run_raw_task
    self._execute_task_with_callbacks(context, test_mode)
  File "/home/airflow/.local/lib/python3.7/site-packages/airflow/models/taskinstance.py", line 1558, in _execute_task_with_callbacks
    result = self._execute_task(context, task_orig)
  File "/home/airflow/.local/lib/python3.7/site-packages/airflow/models/taskinstance.py", line 1628, in _execute_task
    result = execute_callable(context=context)
  File "/opt/airflow/plugins/web/operators/Web_To_GCS_Hook.py", line 58, in execute
    self._copy_file_object(gcs_hook)
  File "/opt/airflow/plugins/web/operators/Web_To_GCS_Hook.py", line 75, in _copy_file_object
    r = requests.get(request_url)
  File "/home/airflow/.local/lib/python3.7/site-packages/requests/api.py", line 73, in get
    return request("get", url, params=params, **kwargs)
  File "/home/airflow/.local/lib/python3.7/site-packages/requests/api.py", line 59, in request
    return session.request(method=method, url=url, **kwargs)
  File "/home/airflow/.local/lib/python3.7/site-packages/requests/sessions.py", line 589, in request
    resp = self.send(prep, **send_kwargs)
  File "/home/airflow/.local/lib/python3.7/site-packages/requests/sessions.py", line 703, in send
    r = adapter.send(request, **kwargs)
  File "/home/airflow/.local/lib/python3.7/site-packages/requests/adapters.py", line 519, in send
    raise ConnectionError(e, request=request)
requests.exceptions.ConnectionError: HTTPSConnectionPool(host='github.com', port=443): Max retries exceeded with url: /DataTalksClub/nyc-tlc-data/releases/download/green/green_tripdata_2019-05.csv.gz (Caused by NewConnectionError('<urllib3.connection.HTTPSConnection object at 0x7fef855033d0>: Failed to establish a new connection: [Errno -3] Temporary failure in name resolution'))

During handling of the above exception, another exception occurred:

Traceback (most recent call last):
  File "/home/airflow/.local/lib/python3.7/site-packages/airflow/models/taskinstance.py", line 2295, in email_alert
    send_email(task.email, subject, html_content)
  File "/home/airflow/.local/lib/python3.7/site-packages/airflow/utils/email.py", line 92, in send_email
    **kwargs,
  File "/home/airflow/.local/lib/python3.7/site-packages/airflow/utils/email.py", line 153, in send_email_smtp
    send_mime_email(e_from=mail_from, e_to=recipients, mime_msg=msg, conn_id=conn_id, dryrun=dryrun)
  File "/home/airflow/.local/lib/python3.7/site-packages/airflow/utils/email.py", line 271, in send_mime_email
    smtp_conn = _get_smtp_connection(smtp_host, smtp_port, smtp_timeout, smtp_ssl)
  File "/home/airflow/.local/lib/python3.7/site-packages/airflow/utils/email.py", line 318, in _get_smtp_connection
    else smtplib.SMTP(host=host, port=port, timeout=timeout)
  File "/usr/local/lib/python3.7/smtplib.py", line 251, in __init__
    (code, msg) = self.connect(host, port)
  File "/usr/local/lib/python3.7/smtplib.py", line 336, in connect
    self.sock = self._get_socket(host, port, self.timeout)
  File "/usr/local/lib/python3.7/smtplib.py", line 307, in _get_socket
    self.source_address)
  File "/usr/local/lib/python3.7/socket.py", line 728, in create_connection
    raise err
  File "/usr/local/lib/python3.7/socket.py", line 716, in create_connection
    sock.connect(sa)
OSError: [Errno 99] Cannot assign requested address

During handling of the above exception, another exception occurred:

Traceback (most recent call last):
  File "/home/airflow/.local/lib/python3.7/site-packages/airflow/models/taskinstance.py", line 1887, in handle_failure
    self.email_alert(error, task)
  File "/home/airflow/.local/lib/python3.7/site-packages/airflow/models/taskinstance.py", line 2297, in email_alert
    send_email(task.email, subject, html_content_err)
  File "/home/airflow/.local/lib/python3.7/site-packages/airflow/utils/email.py", line 92, in send_email
    **kwargs,
  File "/home/airflow/.local/lib/python3.7/site-packages/airflow/utils/email.py", line 153, in send_email_smtp
    send_mime_email(e_from=mail_from, e_to=recipients, mime_msg=msg, conn_id=conn_id, dryrun=dryrun)
  File "/home/airflow/.local/lib/python3.7/site-packages/airflow/utils/email.py", line 271, in send_mime_email
    smtp_conn = _get_smtp_connection(smtp_host, smtp_port, smtp_timeout, smtp_ssl)
  File "/home/airflow/.local/lib/python3.7/site-packages/airflow/utils/email.py", line 318, in _get_smtp_connection
    else smtplib.SMTP(host=host, port=port, timeout=timeout)
  File "/usr/local/lib/python3.7/smtplib.py", line 251, in __init__
    (code, msg) = self.connect(host, port)
  File "/usr/local/lib/python3.7/smtplib.py", line 336, in connect
    self.sock = self._get_socket(host, port, self.timeout)
  File "/usr/local/lib/python3.7/smtplib.py", line 307, in _get_socket
    self.source_address)
  File "/usr/local/lib/python3.7/socket.py", line 728, in create_connection
    raise err
  File "/usr/local/lib/python3.7/socket.py", line 716, in create_connection
    sock.connect(sa)
OSError: [Errno 99] Cannot assign requested address
[2023-10-01T17:12:49.446+0000] {standard_task_runner.py:109} ERROR - Failed to execute job 592 for task download_to_gcs (HTTPSConnectionPool(host='github.com', port=443): Max retries exceeded with url: /DataTalksClub/nyc-tlc-data/releases/download/green/green_tripdata_2019-05.csv.gz (Caused by NewConnectionError('<urllib3.connection.HTTPSConnection object at 0x7fef855033d0>: Failed to establish a new connection: [Errno -3] Temporary failure in name resolution')); 1998)
[2023-10-01T17:12:49.472+0000] {local_task_job_runner.py:225} INFO - Task exited with return code 1
[2023-10-01T17:12:49.800+0000] {taskinstance.py:2653} INFO - 0 downstream tasks scheduled from follow-on schedule check
